<?xml version="1.0"?>
<robot xmlns:xacro="http://www.ros.org/wiki/xacro">

  <!-- _____________RIGHT FRONT wheel ____________-->
  <joint name="right_front_wheel" type="continuous">
    <origin xyz="0.0 0 0" rpy="0 0 0"/>
    <axis xyz="0 0 -1"/>
    <parent link="right_front_motor_link"/>
    <child link="right_front_rev_link"/>
    <dynamics damping="0.7" friction="0"/> <!--Changed from 1 due to meca-->
  </joint>
  
  <link name="right_front_rev_link">
    <visual>
      <origin xyz="-0.085 0.085 0.035" rpy="1.57 0 0"/>
      <geometry>
        <mesh filename="file:$(find kridtbot)/meshes/wheel_assem.STL" scale="0.001 0.001 0.001"/>
      </geometry>
      <material name="orange"/>
    </visual>
    <collision>
      <origin xyz="-0.085 0.085 0.035" rpy="1.57 0 0"/>
      <geometry>
        <mesh filename="file:$(find kridtbot)/meshes/wheel_assem.STL" scale="0.001 0.001 0.001"/>
      </geometry>
      <material name="mesh_color"/>
      <surface>
        <friction>
          <ode>
            <mu>0.2</mu>               <!-- rolling direction -->
            <mu2>0.01</mu2>            <!-- lateral (strafe) direction -->
            <fdir1>1 1 0</fdir1>       <!-- Y-axis for typical wheel -->
            <slip1>0.1</slip1>
            <slip2>0.1</slip2>
          </ode>
        </friction>
     </surface>
    </collision>
    <inertial>
      <mass value="1.01100"/>
      <inertia ixx="5844491.97e-9" ixy="-376.28e-9" ixz="-3671.08e-9" iyy="5842839.83e-9" iyz="-796.72e-9" izz="3646247.90e-9"/>
    </inertial>
  </link>

  <gazebo reference="right_front_rev_link">
    <material>Gazebo/Orange</material>
    <mu1 value="3"/>
    <mu2 value="3"/>
    <slip1 value="1"/>
    <slip2 value="1"/>
    <kp>1000000.0</kp>
    <kd>1.0</kd>
  </gazebo> 


  <!-- _____________LEFT FRONT wheel ____________-->
  <joint name="left_front_wheel" type="continuous">
    <origin xyz="0 0 0" rpy="0 0 0"/>
    <axis xyz="0 0 1"/>
    <parent link="left_front_motor_link"/>
    <child link="left_front_rev_link"/>
    <dynamics damping="0.7" friction="0"/> <!--Changed from 1 due to meca-->
  </joint>

  <link name="left_front_rev_link">
    <visual>
      <origin xyz="-0.085 0.085 0.035" rpy="1.57 0 0"/>
      <geometry>
        <mesh filename="file:$(find kridtbot)/meshes/wheel_assem.STL" scale="0.001 0.001 0.001"/>
      </geometry>
      <material name="orange"/>
    </visual>
    <collision>
      <origin xyz="-0.085 0.085 0.035" rpy="1.57 0 0"/>
      <geometry>
        <mesh filename="file:$(find kridtbot)/meshes/wheel_assem.STL" scale="0.001 0.001 0.001"/>
      </geometry>
      <material name="mesh_color"/>     <surface>
        <friction>
          <ode>
            <mu>0.2</mu>               <!-- rolling direction -->
            <mu2>0.01</mu2>            <!-- lateral (strafe) direction -->
            <fdir1>1 -1 0</fdir1>       <!-- Y-axis for typical wheel -->
            <slip1>0.1</slip1>
            <slip2>0.1</slip2>
          </ode>
        </friction>
     </surface>
    </collision>
    <inertial>
      <mass value="1.01100"/>
      <inertia ixx="5844491.97e-9" ixy="-376.28e-9" ixz="-3671.08e-9" iyy="5842839.83e-9" iyz="-796.72e-9" izz="3646247.90e-9"/>
    </inertial>
  </link>

  <gazebo reference="left_front_rev_link">
    <material>Gazebo/Orange</material>
    <mu1 value="3"/>
    <mu2 value="3"/>
    <slip1 value="1"/>
    <slip2 value="1"/>
    <kp>1000000.0</kp>
    <kd>1.0</kd>
  </gazebo> 


    <!-- _____________LEFT REAR wheel ____________-->
  <joint name="left_rear_wheel" type="continuous">
    <origin xyz="0 0 0" rpy="0 0 0"/>
    <axis xyz="0 0 1"/>
    <parent link="left_rear_motor_link"/>
    <child link="left_rear_rev_link"/>
    <dynamics damping="0.7" friction="0"/> <!--Changed from 1 due to meca-->
  </joint>

  <link name="left_rear_rev_link">
    <visual>
      <origin xyz="-0.085 0.085 0.035" rpy="1.57 0 0"/>
      <geometry>
        <mesh filename="file:$(find kridtbot)/meshes/wheel_assem.STL" scale="0.001 0.001 0.001"/>
      </geometry>
      <material name="orange"/>
    </visual>
    <collision>
      <origin xyz="-0.085 0.085 0.035" rpy="1.57 0 0"/>
      <geometry>
        <mesh filename="file:$(find kridtbot)/meshes/wheel_assem.STL" scale="0.001 0.001 0.001"/>
      </geometry>
      <material name="mesh_color"/>
      <surface>
        <friction>
          <ode>
            <mu>0.2</mu>               <!-- rolling direction -->
            <mu2>0.01</mu2>            <!-- lateral (strafe) direction -->
            <fdir1>1 -1 0</fdir1>       <!-- Y-axis for typical wheel -->
            <slip1>0.1</slip1>
            <slip2>0.1</slip2>
          </ode>
        </friction>
     </surface>
    </collision>
    <inertial>
      <mass value="1.01100"/>
      <inertia ixx="5844491.97e-9" ixy="-376.28e-9" ixz="-3671.08e-9" iyy="5842839.83e-9" iyz="-796.72e-9" izz="3646247.90e-9"/>
    </inertial>
  </link>

  <gazebo reference="left_rear_rev_link">
    <material>Gazebo/Orange</material>
    <mu1 value="3"/>
    <mu2 value="3"/>
    <kp>1000000.0</kp>
    <kd>1.0</kd>
  </gazebo>   
  <!-- _____________RIGHT REAR wheel ____________-->

  <!-- Right Rear joint -->
  <joint name="right_rear_wheel" type="continuous">
    <origin xyz="0 0 0" rpy="0 0 0"/>
    <axis xyz="0 0 -1"/>
    <parent link="right_rear_motor_link"/>
    <child link="right_rear_rev_link"/>
    <dynamics damping="0.7" friction="0"/> <!--Changed from 1 due to meca-->
  </joint>


<!-- Right Rear wheel-->
<link name="right_rear_rev_link">
    <visual>
      <origin xyz="-0.085 0.085 0.035" rpy="1.57 0 0"/>
      <geometry>
        <mesh filename="file:$(find kridtbot)/meshes/wheel_assem.STL" scale="0.001 0.001 0.001"/> 
      </geometry>
      <material name="orange"/>
    </visual>
    <collision>
       <origin xyz="-0.085 0.085 0.035" rpy="1.57 0 0"/> 
      <geometry>
        <mesh filename="file:$(find kridtbot)/meshes/wheel_assem.STL" scale="0.001 0.001 0.001"/> 
      </geometry>
      <material name="mesh_color"/>
      <surface>
        <friction>
          <ode>
            <mu>0.2</mu>               <!-- rolling direction -->
            <mu2>0.01</mu2>            <!-- lateral (strafe) direction -->
            <fdir1>1 -1 0</fdir1>       <!-- Y-axis for typical wheel -->
            <slip1>0.1</slip1>
            <slip2>0.1</slip2>
          </ode>
        </friction>
      </surface>
    </collision>
    <inertial>
      <mass value="1.01100"/>
      <inertia ixx="5844491.97e-9" ixy="-376.28e-9" ixz="-3671.08e-9" iyy="5842839.83e-9" iyz="-796.72e-9" izz="3646247.90e-9"/>
    </inertial>
  </link>

  <gazebo reference="right_rear_rev_link">
    <material>Gazebo/Orange</material>
    <mu1 value="3"/>
    <mu2 value="3"/>
    <slip1 value="1"/>
    <slip2 value="1"/>
    <kp>1000000.0</kp>
    <kd>1.0</kd>
  </gazebo> 


</robot>